Traceback (most recent call last):
  File "/usr/local/lib/python3.10/dist-packages/jupyter_cache/executors/utils.py", line 58, in single_nb_execution
    executenb(
  File "/usr/local/lib/python3.10/dist-packages/nbclient/client.py", line 1305, in execute
    return NotebookClient(nb=nb, resources=resources, km=km, **kwargs).execute()
  File "/usr/local/lib/python3.10/dist-packages/jupyter_core/utils/__init__.py", line 173, in wrapped
    return loop.run_until_complete(inner)
  File "/usr/lib/python3.10/asyncio/base_events.py", line 649, in run_until_complete
    return future.result()
  File "/usr/local/lib/python3.10/dist-packages/nbclient/client.py", line 705, in async_execute
    await self.async_execute_cell(
  File "/usr/local/lib/python3.10/dist-packages/nbclient/client.py", line 1058, in async_execute_cell
    await self._check_raise_for_error(cell, cell_index, exec_reply)
  File "/usr/local/lib/python3.10/dist-packages/nbclient/client.py", line 914, in _check_raise_for_error
    raise CellExecutionError.from_cell_and_msg(cell, exec_reply_content)
nbclient.exceptions.CellExecutionError: An error occurred while executing the following cell:
------------------
import requests
from bs4 import BeautifulSoup
import nltk

# Unduh konten halaman web berita
url = "https://www.antaranews.com/berita/3803331/kaesang-psi-tidak-ingin-ikut-campur-urusan-gibran-dengan-pdip"
response = requests.get(url)
html = response.text

# Parsing halaman web menggunakan BeautifulSoup
soup = BeautifulSoup(html, 'html.parser')

# Ekstraksi teks dari elemen-elemen yang berisi berita
article = soup.find('div' ,class_="post-content clearfix")  # Sesuaikan dengan struktur HTML halaman web berita
article_text = article.get_text()

# Tokenisasi teks menjadi kalimat menggunakan nltk
nltk.download('punkt')  # Pastikan Anda sudah mengunduh tokenisasi kalimat nltk
sentences = nltk.sent_tokenize(article_text)

# Cetak kalimat-kalimat
for sentence in sentences:
    print(sentence)

------------------


[0;31m---------------------------------------------------------------------------[0m
[0;31mConnectionRefusedError[0m                    Traceback (most recent call last)
[0;32m/usr/local/lib/python3.10/dist-packages/urllib3/connection.py[0m in [0;36m_new_conn[0;34m(self)[0m
[1;32m    202[0m         [0;32mtry[0m[0;34m:[0m[0;34m[0m[0;34m[0m[0m
[0;32m--> 203[0;31m             sock = connection.create_connection(
[0m[1;32m    204[0m                 [0;34m([0m[0mself[0m[0;34m.[0m[0m_dns_host[0m[0;34m,[0m [0mself[0m[0;34m.[0m[0mport[0m[0;34m)[0m[0;34m,[0m[0;34m[0m[0;34m[0m[0m

[0;32m/usr/local/lib/python3.10/dist-packages/urllib3/util/connection.py[0m in [0;36mcreate_connection[0;34m(address, timeout, source_address, socket_options)[0m
[1;32m     84[0m         [0;32mtry[0m[0;34m:[0m[0;34m[0m[0;34m[0m[0m
[0;32m---> 85[0;31m             [0;32mraise[0m [0merr[0m[0;34m[0m[0;34m[0m[0m
[0m[1;32m     86[0m         [0;32mfinally[0m[0;34m:[0m[0;34m[0m[0;34m[0m[0m

[0;32m/usr/local/lib/python3.10/dist-packages/urllib3/util/connection.py[0m in [0;36mcreate_connection[0;34m(address, timeout, source_address, socket_options)[0m
[1;32m     72[0m                 [0msock[0m[0;34m.[0m[0mbind[0m[0;34m([0m[0msource_address[0m[0;34m)[0m[0;34m[0m[0;34m[0m[0m
[0;32m---> 73[0;31m             [0msock[0m[0;34m.[0m[0mconnect[0m[0;34m([0m[0msa[0m[0;34m)[0m[0;34m[0m[0;34m[0m[0m
[0m[1;32m     74[0m             [0;31m# Break explicitly a reference cycle[0m[0;34m[0m[0;34m[0m[0m

[0;31mConnectionRefusedError[0m: [Errno 111] Connection refused

The above exception was the direct cause of the following exception:

[0;31mNewConnectionError[0m                        Traceback (most recent call last)
[0;32m/usr/local/lib/python3.10/dist-packages/urllib3/connectionpool.py[0m in [0;36murlopen[0;34m(self, method, url, body, headers, retries, redirect, assert_same_host, timeout, pool_timeout, release_conn, chunked, body_pos, preload_content, decode_content, **response_kw)[0m
[1;32m    790[0m             [0;31m# Make the request on the HTTPConnection object[0m[0;34m[0m[0;34m[0m[0m
[0;32m--> 791[0;31m             response = self._make_request(
[0m[1;32m    792[0m                 [0mconn[0m[0;34m,[0m[0;34m[0m[0;34m[0m[0m

[0;32m/usr/local/lib/python3.10/dist-packages/urllib3/connectionpool.py[0m in [0;36m_make_request[0;34m(self, conn, method, url, body, headers, retries, timeout, chunked, response_conn, preload_content, decode_content, enforce_content_length)[0m
[1;32m    491[0m                 [0mnew_e[0m [0;34m=[0m [0m_wrap_proxy_error[0m[0;34m([0m[0mnew_e[0m[0;34m,[0m [0mconn[0m[0;34m.[0m[0mproxy[0m[0;34m.[0m[0mscheme[0m[0;34m)[0m[0;34m[0m[0;34m[0m[0m
[0;32m--> 492[0;31m             [0;32mraise[0m [0mnew_e[0m[0;34m[0m[0;34m[0m[0m
[0m[1;32m    493[0m [0;34m[0m[0m

[0;32m/usr/local/lib/python3.10/dist-packages/urllib3/connectionpool.py[0m in [0;36m_make_request[0;34m(self, conn, method, url, body, headers, retries, timeout, chunked, response_conn, preload_content, decode_content, enforce_content_length)[0m
[1;32m    467[0m             [0;32mtry[0m[0;34m:[0m[0;34m[0m[0;34m[0m[0m
[0;32m--> 468[0;31m                 [0mself[0m[0;34m.[0m[0m_validate_conn[0m[0;34m([0m[0mconn[0m[0;34m)[0m[0;34m[0m[0;34m[0m[0m
[0m[1;32m    469[0m             [0;32mexcept[0m [0;34m([0m[0mSocketTimeout[0m[0;34m,[0m [0mBaseSSLError[0m[0;34m)[0m [0;32mas[0m [0me[0m[0;34m:[0m[0;34m[0m[0;34m[0m[0m

[0;32m/usr/local/lib/python3.10/dist-packages/urllib3/connectionpool.py[0m in [0;36m_validate_conn[0;34m(self, conn)[0m
[1;32m   1096[0m         [0;32mif[0m [0mconn[0m[0;34m.[0m[0mis_closed[0m[0;34m:[0m[0;34m[0m[0;34m[0m[0m
[0;32m-> 1097[0;31m             [0mconn[0m[0;34m.[0m[0mconnect[0m[0;34m([0m[0;34m)[0m[0;34m[0m[0;34m[0m[0m
[0m[1;32m   1098[0m [0;34m[0m[0m

[0;32m/usr/local/lib/python3.10/dist-packages/urllib3/connection.py[0m in [0;36mconnect[0;34m(self)[0m
[1;32m    610[0m         [0msock[0m[0;34m:[0m [0msocket[0m[0;34m.[0m[0msocket[0m [0;34m|[0m [0mssl[0m[0;34m.[0m[0mSSLSocket[0m[0;34m[0m[0;34m[0m[0m
[0;32m--> 611[0;31m         [0mself[0m[0;34m.[0m[0msock[0m [0;34m=[0m [0msock[0m [0;34m=[0m [0mself[0m[0;34m.[0m[0m_new_conn[0m[0;34m([0m[0;34m)[0m[0;34m[0m[0;34m[0m[0m
[0m[1;32m    612[0m         [0mserver_hostname[0m[0;34m:[0m [0mstr[0m [0;34m=[0m [0mself[0m[0;34m.[0m[0mhost[0m[0;34m[0m[0;34m[0m[0m

[0;32m/usr/local/lib/python3.10/dist-packages/urllib3/connection.py[0m in [0;36m_new_conn[0;34m(self)[0m
[1;32m    217[0m         [0;32mexcept[0m [0mOSError[0m [0;32mas[0m [0me[0m[0;34m:[0m[0;34m[0m[0;34m[0m[0m
[0;32m--> 218[0;31m             raise NewConnectionError(
[0m[1;32m    219[0m                 [0mself[0m[0;34m,[0m [0;34mf"Failed to establish a new connection: {e}"[0m[0;34m[0m[0;34m[0m[0m

[0;31mNewConnectionError[0m: <urllib3.connection.HTTPSConnection object at 0x7da6b1762e60>: Failed to establish a new connection: [Errno 111] Connection refused

The above exception was the direct cause of the following exception:

[0;31mMaxRetryError[0m                             Traceback (most recent call last)
[0;32m/usr/local/lib/python3.10/dist-packages/requests/adapters.py[0m in [0;36msend[0;34m(self, request, stream, timeout, verify, cert, proxies)[0m
[1;32m    485[0m         [0;32mtry[0m[0;34m:[0m[0;34m[0m[0;34m[0m[0m
[0;32m--> 486[0;31m             resp = conn.urlopen(
[0m[1;32m    487[0m                 [0mmethod[0m[0;34m=[0m[0mrequest[0m[0;34m.[0m[0mmethod[0m[0;34m,[0m[0;34m[0m[0;34m[0m[0m

[0;32m/usr/local/lib/python3.10/dist-packages/urllib3/connectionpool.py[0m in [0;36murlopen[0;34m(self, method, url, body, headers, retries, redirect, assert_same_host, timeout, pool_timeout, release_conn, chunked, body_pos, preload_content, decode_content, **response_kw)[0m
[1;32m    844[0m [0;34m[0m[0m
[0;32m--> 845[0;31m             retries = retries.increment(
[0m[1;32m    846[0m                 [0mmethod[0m[0;34m,[0m [0murl[0m[0;34m,[0m [0merror[0m[0;34m=[0m[0mnew_e[0m[0;34m,[0m [0m_pool[0m[0;34m=[0m[0mself[0m[0;34m,[0m [0m_stacktrace[0m[0;34m=[0m[0msys[0m[0;34m.[0m[0mexc_info[0m[0;34m([0m[0;34m)[0m[0;34m[[0m[0;36m2[0m[0;34m][0m[0;34m[0m[0;34m[0m[0m

[0;32m/usr/local/lib/python3.10/dist-packages/urllib3/util/retry.py[0m in [0;36mincrement[0;34m(self, method, url, response, error, _pool, _stacktrace)[0m
[1;32m    514[0m             [0mreason[0m [0;34m=[0m [0merror[0m [0;32mor[0m [0mResponseError[0m[0;34m([0m[0mcause[0m[0;34m)[0m[0;34m[0m[0;34m[0m[0m
[0;32m--> 515[0;31m             [0;32mraise[0m [0mMaxRetryError[0m[0;34m([0m[0m_pool[0m[0;34m,[0m [0murl[0m[0;34m,[0m [0mreason[0m[0;34m)[0m [0;32mfrom[0m [0mreason[0m  [0;31m# type: ignore[arg-type][0m[0;34m[0m[0;34m[0m[0m
[0m[1;32m    516[0m [0;34m[0m[0m

[0;31mMaxRetryError[0m: HTTPSConnectionPool(host='www.antaranews.com', port=443): Max retries exceeded with url: /berita/3803331/kaesang-psi-tidak-ingin-ikut-campur-urusan-gibran-dengan-pdip (Caused by NewConnectionError('<urllib3.connection.HTTPSConnection object at 0x7da6b1762e60>: Failed to establish a new connection: [Errno 111] Connection refused'))

During handling of the above exception, another exception occurred:

[0;31mConnectionError[0m                           Traceback (most recent call last)
[0;32m<ipython-input-1-e5ea5becb547>[0m in [0;36m<cell line: 7>[0;34m()[0m
[1;32m      5[0m [0;31m# Unduh konten halaman web berita[0m[0;34m[0m[0;34m[0m[0m
[1;32m      6[0m [0murl[0m [0;34m=[0m [0;34m"https://www.antaranews.com/berita/3803331/kaesang-psi-tidak-ingin-ikut-campur-urusan-gibran-dengan-pdip"[0m[0;34m[0m[0;34m[0m[0m
[0;32m----> 7[0;31m [0mresponse[0m [0;34m=[0m [0mrequests[0m[0;34m.[0m[0mget[0m[0;34m([0m[0murl[0m[0;34m)[0m[0;34m[0m[0;34m[0m[0m
[0m[1;32m      8[0m [0mhtml[0m [0;34m=[0m [0mresponse[0m[0;34m.[0m[0mtext[0m[0;34m[0m[0;34m[0m[0m
[1;32m      9[0m [0;34m[0m[0m

[0;32m/usr/local/lib/python3.10/dist-packages/requests/api.py[0m in [0;36mget[0;34m(url, params, **kwargs)[0m
[1;32m     71[0m     """
[1;32m     72[0m [0;34m[0m[0m
[0;32m---> 73[0;31m     [0;32mreturn[0m [0mrequest[0m[0;34m([0m[0;34m"get"[0m[0;34m,[0m [0murl[0m[0;34m,[0m [0mparams[0m[0;34m=[0m[0mparams[0m[0;34m,[0m [0;34m**[0m[0mkwargs[0m[0;34m)[0m[0;34m[0m[0;34m[0m[0m
[0m[1;32m     74[0m [0;34m[0m[0m
[1;32m     75[0m [0;34m[0m[0m

[0;32m/usr/local/lib/python3.10/dist-packages/requests/api.py[0m in [0;36mrequest[0;34m(method, url, **kwargs)[0m
[1;32m     57[0m     [0;31m# cases, and look like a memory leak in others.[0m[0;34m[0m[0;34m[0m[0m
[1;32m     58[0m     [0;32mwith[0m [0msessions[0m[0;34m.[0m[0mSession[0m[0;34m([0m[0;34m)[0m [0;32mas[0m [0msession[0m[0;34m:[0m[0;34m[0m[0;34m[0m[0m
[0;32m---> 59[0;31m         [0;32mreturn[0m [0msession[0m[0;34m.[0m[0mrequest[0m[0;34m([0m[0mmethod[0m[0;34m=[0m[0mmethod[0m[0;34m,[0m [0murl[0m[0;34m=[0m[0murl[0m[0;34m,[0m [0;34m**[0m[0mkwargs[0m[0;34m)[0m[0;34m[0m[0;34m[0m[0m
[0m[1;32m     60[0m [0;34m[0m[0m
[1;32m     61[0m [0;34m[0m[0m

[0;32m/usr/local/lib/python3.10/dist-packages/requests/sessions.py[0m in [0;36mrequest[0;34m(self, method, url, params, data, headers, cookies, files, auth, timeout, allow_redirects, proxies, hooks, stream, verify, cert, json)[0m
[1;32m    587[0m         }
[1;32m    588[0m         [0msend_kwargs[0m[0;34m.[0m[0mupdate[0m[0;34m([0m[0msettings[0m[0;34m)[0m[0;34m[0m[0;34m[0m[0m
[0;32m--> 589[0;31m         [0mresp[0m [0;34m=[0m [0mself[0m[0;34m.[0m[0msend[0m[0;34m([0m[0mprep[0m[0;34m,[0m [0;34m**[0m[0msend_kwargs[0m[0;34m)[0m[0;34m[0m[0;34m[0m[0m
[0m[1;32m    590[0m [0;34m[0m[0m
[1;32m    591[0m         [0;32mreturn[0m [0mresp[0m[0;34m[0m[0;34m[0m[0m

[0;32m/usr/local/lib/python3.10/dist-packages/requests/sessions.py[0m in [0;36msend[0;34m(self, request, **kwargs)[0m
[1;32m    701[0m [0;34m[0m[0m
[1;32m    702[0m         [0;31m# Send the request[0m[0;34m[0m[0;34m[0m[0m
[0;32m--> 703[0;31m         [0mr[0m [0;34m=[0m [0madapter[0m[0;34m.[0m[0msend[0m[0;34m([0m[0mrequest[0m[0;34m,[0m [0;34m**[0m[0mkwargs[0m[0;34m)[0m[0;34m[0m[0;34m[0m[0m
[0m[1;32m    704[0m [0;34m[0m[0m
[1;32m    705[0m         [0;31m# Total elapsed time of the request (approximately)[0m[0;34m[0m[0;34m[0m[0m

[0;32m/usr/local/lib/python3.10/dist-packages/requests/adapters.py[0m in [0;36msend[0;34m(self, request, stream, timeout, verify, cert, proxies)[0m
[1;32m    517[0m                 [0;32mraise[0m [0mSSLError[0m[0;34m([0m[0me[0m[0;34m,[0m [0mrequest[0m[0;34m=[0m[0mrequest[0m[0;34m)[0m[0;34m[0m[0;34m[0m[0m
[1;32m    518[0m [0;34m[0m[0m
[0;32m--> 519[0;31m             [0;32mraise[0m [0mConnectionError[0m[0;34m([0m[0me[0m[0;34m,[0m [0mrequest[0m[0;34m=[0m[0mrequest[0m[0;34m)[0m[0;34m[0m[0;34m[0m[0m
[0m[1;32m    520[0m [0;34m[0m[0m
[1;32m    521[0m         [0;32mexcept[0m [0mClosedPoolError[0m [0;32mas[0m [0me[0m[0;34m:[0m[0;34m[0m[0;34m[0m[0m

[0;31mConnectionError[0m: HTTPSConnectionPool(host='www.antaranews.com', port=443): Max retries exceeded with url: /berita/3803331/kaesang-psi-tidak-ingin-ikut-campur-urusan-gibran-dengan-pdip (Caused by NewConnectionError('<urllib3.connection.HTTPSConnection object at 0x7da6b1762e60>: Failed to establish a new connection: [Errno 111] Connection refused'))

